Workbook

Sheet previsoes
A1: Despesa | B1: Valor | C1: Parcelas | D1: Valor da Parcela | E1: Data Início | F1: Data Fim | G1: Parcelas | H1: Responsável
A2: Emprestimo Dora | B2: 133592.22 | C2: 24 | D2: =IFERROR(B2/C2, "") -> 5566.3425 | E2: 46235 | F2: =IFERROR(IF(E2<>"", EDATE(E2, C2),""), "") -> 46966 | G2: =IF(F2<>"",DATEDIF(E2,F2,"M"),"") -> 24 | H2: Ivana
A3: Nova etapa do jardim | B3: 10000 | C3: 3 | D3: =IFERROR(B3/C3, "") -> 3333.3333 | E3: 46296 | F3: =IFERROR(IF(E3<>"", EDATE(E3, C3),""), "") -> 46388 | G3: =IF(F3<>"",DATEDIF(E3,F3,"M"),"") -> 3 | H3: Samuel
A4: 13o Jaque | B4: 3000 | C4: 1 | D4: =IFERROR(B4/C4, "") -> 3000 | E4: 46333 | F4: =IFERROR(IF(E4<>"", EDATE(E4, C4),""), "") -> 46363 | G4: 1 | H4: Ivana
A5: 13o Alexandre | B5: 500 | C5: 1 | D5: 1000 | E5: 46357 | F5: =IFERROR(IF(E5<>"", EDATE(E5, C5),""), "") -> 46388 | G5: 1 | H5: Samuel
D7: =IFERROR(B7/C7, "")
D8: =IFERROR(B8/C8, "")
D9: =IFERROR(B9/C9, "")
D10: =IFERROR(B10/C10, "")

Sheet contas
A1: Conta | B1: Saldo | C1: Banco | D1: Data | E1: Responsável | F1: Próximo mês | G1: chave_ano_mes | H1: Logo
A2: BTG | B2: 5321.81 | C2: BTG | D2: 46201 | E2: Samuel | F2: =EDATE(D2,1) -> 46231 | G2: =IFERROR(IF(D2<>"",TEXT(D2, "yyyy-mm"),""),"") -> 2026-06 | H2: {=IF(A2<>"",INDEX(icons!B:B, MATCH(A2,icons!A:A,0)),"")} -> https://play-lh.googleusercontent.com/O5Z9jsv79WTfdd37TFPyIwAQjNotIZTTEC6sOXaD3_2IXrMjtOI2ZnqReOicI3TgmqI
A3: BB | B3: 50 | C3: BB | D3: 46026 | E3: Ivana | F3: =EDATE(D3,1) -> 46057 | G3: =IFERROR(IF(D3<>"",TEXT(D3, "yyyy-mm"),""),"") -> 2026-01 | H3: {=IF(A3<>"",INDEX(icons!B:B, MATCH(A3,icons!A:A,0)),"")} -> https://encrypted-tbn0.gstatic.com/images?q=tbn:ANd9GcSJysUOK4O3SeA8O0Zzn289tU16vROXFtKvEQ&s
A4: Santander | B4: 200 | C4: Santander | D4: 46026 | E4: Ivana | F4: =EDATE(D4,1) -> 46057 | G4: =IFERROR(IF(D4<>"",TEXT(D4, "yyyy-mm"),""),"") -> 2026-01 | H4: {=IF(A4<>"",INDEX(icons!B:B, MATCH(A4,icons!A:A,0)),"")} -> https://assets.hgbrasil.com/finance/companies/big/santander-br.png
A5: Caixa | B5: 9200 | C5: Caixa | D5: 46026 | E5: Ivana | F5: =EDATE(D5,1) -> 46057 | G5: =IFERROR(IF(D5<>"",TEXT(D5, "yyyy-mm"),""),"") -> 2026-01 | H5: {=IF(A5<>"",INDEX(icons!B:B, MATCH(A5,icons!A:A,0)),"")} -> https://raichu-uploads.s3.amazonaws.com/logo_caixa-economica-federal_q9tWzt.png
A6: Revolut | B6: 0 | C6: BTG | D6: 46201 | E6: Ivana | F6: =EDATE(D6,1) -> 46231 | G6: =IFERROR(IF(D6<>"",TEXT(D6, "yyyy-mm"),""),"") -> 2026-06 | H6: {=IF(A6<>"",INDEX(icons!B:B, MATCH(A6,icons!A:A,0)),"")} -> https://www.logo.wine/a/logo/Revolut/Revolut-Logo.wine.svg
A7: Revolut | B7: 0 | C7: BTG | D7: 46201 | E7: Samuel | F7: =EDATE(D7,1) -> 46231 | G7: =IFERROR(IF(D7<>"",TEXT(D7, "yyyy-mm"),""),"") -> 2026-06 | H7: {=IF(A7<>"",INDEX(icons!B:B, MATCH(A7,icons!A:A,0)),"")} -> https://www.logo.wine/a/logo/Revolut/Revolut-Logo.wine.svg
G8: =IFERROR(IF(F8<>"",TEXT(F8, "yyyy-mm"),""),"") | H8: {=IF(A8<>"",INDEX(icons!B:B, MATCH(A8,icons!A:A,0)),"")}
G9: =IFERROR(IF(F9<>"",TEXT(F9, "yyyy-mm"),""),"") | H9: {=IF(A9<>"",INDEX(icons!B:B, MATCH(A9,icons!A:A,0)),"")}
G10: =IFERROR(IF(F10<>"",TEXT(F10, "yyyy-mm"),""),"") | H10: {=IF(A10<>"",INDEX(cartoes!E:E, MATCH(A10,cartoes!A:A,0)),"")}
G11: =IFERROR(IF(F11<>"",TEXT(F11, "yyyy-mm"),""),"") | H11: {=IF(A11<>"",INDEX(cartoes!E:E, MATCH(A11,cartoes!A:A,0)),"")}
G12: =IFERROR(IF(F12<>"",TEXT(F12, "yyyy-mm"),""),"") | H12: {=IF(A12<>"",INDEX(cartoes!E:E, MATCH(A12,cartoes!A:A,0)),"")}
G13: =IFERROR(IF(F13<>"",TEXT(F13, "yyyy-mm"),""),"") | H13: {=IF(A13<>"",INDEX(cartoes!E:E, MATCH(A13,cartoes!A:A,0)),"")}
G14: =IFERROR(IF(F14<>"",TEXT(F14, "yyyy-mm"),""),"") | H14: {=IF(A14<>"",INDEX(cartoes!E:E, MATCH(A14,cartoes!A:A,0)),"")}

Sheet cartoes
A1: Cartão | B1: Dia do Vencimento | C1: Valor base | D1: Responsável | E1: Logo
A2: BTG | B2: 13 | C2: 500 | D2: samuel | E2: {=IFERROR(IF(A2<>"", INDEX(icons!B:B, MATCH(A2,icons!A:A,0)),""),"")} -> https://play-lh.googleusercontent.com/O5Z9jsv79WTfdd37TFPyIwAQjNotIZTTEC6sOXaD3_2IXrMjtOI2ZnqReOicI3TgmqI
A3: Elo | B3: 10 | C3: 0 | D3: ivana | E3: {=IFERROR(IF(A3<>"", INDEX(icons!B:B, MATCH(A3,icons!A:A,0)),""),"")} -> https://www.publicitarioscriativos.com/wp-content/uploads/2024/05/442415684_844179061088736_7389654490654112245_n.jpg
A4: AA - Santander | B4: 10 | C4: 12000 | D4: ivana | E4: {=IFERROR(IF(A4<>"", INDEX(icons!B:B, MATCH(A4,icons!A:A,0)),""),"")} -> https://assets.hgbrasil.com/finance/companies/big/santander-br.png
A5: Unq - Santander | B5: 21 | C5: 0 | D5: ivana | E5: {=IFERROR(IF(A5<>"", INDEX(icons!B:B, MATCH(A5,icons!A:A,0)),""),"")} -> https://assets.hgbrasil.com/finance/companies/big/santander-br.png
A6: Azul - Itau | B6: 23 | C6: 5000 | D6: ivana | E6: {=IFERROR(IF(A6<>"", INDEX(icons!B:B, MATCH(A6,icons!A:A,0)),""),"")} -> https://blogger.googleusercontent.com/img/b/R29vZ2xl/AVvXsEjl4gJnZqQz-Wz4S_mjixZgRnvCTYbIzoYs34k0e5qslitovNsUJbX8owsXEISCuHSFYbZ09JrRBr6sH3QaUm9TltnTRlyFnl9W2TW2T1iIMnB9MKpoMWMpZi0lY0uBU5cSYKi5i2Uy0XQucH0orBc8QCDtkRIkSB6SnaBhBmeB-SeGFVUiKF93/s510/itau%20logo%20novo%201.jpg
A7: Revolut | B7: 21 | D7: ivana | E7: {=IFERROR(IF(A7<>"", INDEX(icons!B:B, MATCH(A7,icons!A:A,0)),""),"")} -> https://www.logo.wine/a/logo/Revolut/Revolut-Logo.wine.svg
E8: {=IFERROR(IF(A8<>"", INDEX(icons!B:B, MATCH(A8,icons!A:A,0)),""),"")}
E9: {=IFERROR(IF(A9<>"", INDEX(icons!B:B, MATCH(A9,icons!A:A,0)),""),"")}
E10: {=IFERROR(IF(A10<>"", INDEX(icons!B:B, MATCH(A10,icons!A:A,0)),""),"")}
E11: {=IFERROR(IF(A11<>"", INDEX(icons!B:B, MATCH(A11,icons!A:A,0)),""),"")}
E12: {=IFERROR(IF(A12<>"", INDEX(icons!B:B, MATCH(A12,icons!A:A,0)),""),"")}
E13: {=IFERROR(IF(A13<>"", INDEX(icons!B:B, MATCH(A13,icons!A:A,0)),""),"")}
E14: {=IFERROR(IF(A14<>"", INDEX(icons!B:B, MATCH(A14,icons!A:A,0)),""),"")}
E15: {=IFERROR(IF(A15<>"", INDEX(icons!B:B, MATCH(A15,icons!A:A,0)),""),"")}
E16: {=IFERROR(IF(A16<>"", INDEX(icons!B:B, MATCH(A16,icons!A:A,0)),""),"")}
E17: {=IFERROR(IF(A17<>"", INDEX(icons!B:B, MATCH(A17,icons!A:A,0)),""),"")}

Sheet gasto_cartao
A1: Cartão | B1: Fatura | C1: Data | D1: Responsável | E1: chave_ano_mes | F1: Logo
A2: =cartoes!A2 -> BTG | B2: 2661.49 | C2: 45851 | D2: Samuel | E2: =IFERROR(IF(C2<>"",TEXT(C2, "yyyy-mm"),""),"") -> 2025-07 | F2: {=IF(A2<>"",INDEX(icons!B:B, MATCH(A2,icons!A:A,0)),"")} -> https://play-lh.googleusercontent.com/O5Z9jsv79WTfdd37TFPyIwAQjNotIZTTEC6sOXaD3_2IXrMjtOI2ZnqReOicI3TgmqI
A3: AA - Santander | B3: 31080.31 | C3: 45848 | D3: Ivana | E3: =IFERROR(IF(C3<>"",TEXT(C3, "yyyy-mm"),""),"") -> 2025-07 | F3: {=IF(A3<>"",INDEX(icons!B:B, MATCH(A3,icons!A:A,0)),"")} -> https://assets.hgbrasil.com/finance/companies/big/santander-br.png
A4: Unq - Santander | B4: 3379.3 | C4: 45859 | D4: Ivana | E4: =IFERROR(IF(C4<>"",TEXT(C4, "yyyy-mm"),""),"") -> 2025-07 | F4: {=IF(A4<>"",INDEX(icons!B:B, MATCH(A4,icons!A:A,0)),"")} -> https://assets.hgbrasil.com/finance/companies/big/santander-br.png
A5: Elo | B5: 8010.61 | C5: 45848 | D5: Ivana | E5: =IFERROR(IF(C5<>"",TEXT(C5, "yyyy-mm"),""),"") -> 2025-07 | F5: {=IF(A5<>"",INDEX(icons!B:B, MATCH(A5,icons!A:A,0)),"")} -> https://www.publicitarioscriativos.com/wp-content/uploads/2024/05/442415684_844179061088736_7389654490654112245_n.jpg
A6: Azul - Itau | B6: 6704.46 | C6: 45859 | D6: Ivana | E6: =IFERROR(IF(C6<>"",TEXT(C6, "yyyy-mm"),""),"") -> 2025-07 | F6: {=IF(A6<>"",INDEX(icons!B:B, MATCH(A6,icons!A:A,0)),"")} -> https://blogger.googleusercontent.com/img/b/R29vZ2xl/AVvXsEjl4gJnZqQz-Wz4S_mjixZgRnvCTYbIzoYs34k0e5qslitovNsUJbX8owsXEISCuHSFYbZ09JrRBr6sH3QaUm9TltnTRlyFnl9W2TW2T1iIMnB9MKpoMWMpZi0lY0uBU5cSYKi5i2Uy0XQucH0orBc8QCDtkRIkSB6SnaBhBmeB-SeGFVUiKF93/s510/itau%20logo%20novo%201.jpg
A7: =cartoes!A2 -> BTG | B7: 2448.06 | C7: 45882 | D7: Samuel | E7: =IFERROR(IF(C7<>"",TEXT(C7, "yyyy-mm"),""),"") -> 2025-08 | F7: {=IF(A7<>"",INDEX(icons!B:B, MATCH(A7,icons!A:A,0)),"")} -> https://play-lh.googleusercontent.com/O5Z9jsv79WTfdd37TFPyIwAQjNotIZTTEC6sOXaD3_2IXrMjtOI2ZnqReOicI3TgmqI
A8: AA - Santander | B8: 22768.92 | C8: 45879 | D8: Ivana | E8: =IFERROR(IF(C8<>"",TEXT(C8, "yyyy-mm"),""),"") -> 2025-08 | F8: {=IF(A8<>"",INDEX(icons!B:B, MATCH(A8,icons!A:A,0)),"")} -> https://assets.hgbrasil.com/finance/companies/big/santander-br.png
A9: Unq - Santander | B9: 1682.4 | C9: 45890 | D9: Ivana | E9: =IFERROR(IF(C9<>"",TEXT(C9, "yyyy-mm"),""),"") -> 2025-08 | F9: {=IF(A9<>"",INDEX(icons!B:B, MATCH(A9,icons!A:A,0)),"")} -> https://assets.hgbrasil.com/finance/companies/big/santander-br.png
A10: Elo | B10: 6719.35 | C10: 45879 | D10: Ivana | E10: =IFERROR(IF(C10<>"",TEXT(C10, "yyyy-mm"),""),"") -> 2025-08 | F10: {=IF(A10<>"",INDEX(icons!B:B, MATCH(A10,icons!A:A,0)),"")} -> https://www.publicitarioscriativos.com/wp-content/uploads/2024/05/442415684_844179061088736_7389654490654112245_n.jpg
A11: Azul - Itau | B11: 2093.27 | C11: 45890 | D11: Ivana | E11: =IFERROR(IF(C11<>"",TEXT(C11, "yyyy-mm"),""),"") -> 2025-08 | F11: {=IF(A11<>"",INDEX(icons!B:B, MATCH(A11,icons!A:A,0)),"")} -> https://blogger.googleusercontent.com/img/b/R29vZ2xl/AVvXsEjl4gJnZqQz-Wz4S_mjixZgRnvCTYbIzoYs34k0e5qslitovNsUJbX8owsXEISCuHSFYbZ09JrRBr6sH3QaUm9TltnTRlyFnl9W2TW2T1iIMnB9MKpoMWMpZi0lY0uBU5cSYKi5i2Uy0XQucH0orBc8QCDtkRIkSB6SnaBhBmeB-SeGFVUiKF93/s510/itau%20logo%20novo%201.jpg
A12: =cartoes!A2 -> BTG | B12: 2288.23 | C12: 45913 | D12: Samuel | E12: =IFERROR(IF(C12<>"",TEXT(C12, "yyyy-mm"),""),"") -> 2025-09 | F12: {=IF(A12<>"",INDEX(icons!B:B, MATCH(A12,icons!A:A,0)),"")} -> https://play-lh.googleusercontent.com/O5Z9jsv79WTfdd37TFPyIwAQjNotIZTTEC6sOXaD3_2IXrMjtOI2ZnqReOicI3TgmqI
A13: AA - Santander | B13: 20705.61 | C13: 45910 | D13: Ivana | E13: =IFERROR(IF(C13<>"",TEXT(C13, "yyyy-mm"),""),"") -> 2025-09 | F13: {=IF(A13<>"",INDEX(icons!B:B, MATCH(A13,icons!A:A,0)),"")} -> https://assets.hgbrasil.com/finance/companies/big/santander-br.png
A14: Unq - Santander | B14: 7805.91 | C14: 45921 | D14: Ivana | E14: =IFERROR(IF(C14<>"",TEXT(C14, "yyyy-mm"),""),"") -> 2025-09 | F14: {=IF(A14<>"",INDEX(icons!B:B, MATCH(A14,icons!A:A,0)),"")} -> https://assets.hgbrasil.com/finance/companies/big/santander-br.png
A15: Elo | B15: =222.36+234.15+1100 -> 1556.51 | C15: 45910 | D15: Ivana | E15: =IFERROR(IF(C15<>"",TEXT(C15, "yyyy-mm"),""),"") -> 2025-09 | F15: {=IF(A15<>"",INDEX(icons!B:B, MATCH(A15,icons!A:A,0)),"")} -> https://www.publicitarioscriativos.com/wp-content/uploads/2024/05/442415684_844179061088736_7389654490654112245_n.jpg
A16: Azul - Itau | B16: 5020.49 | C16: 45921 | D16: Ivana | E16: =IFERROR(IF(C16<>"",TEXT(C16, "yyyy-mm"),""),"") -> 2025-09 | F16: {=IF(A16<>"",INDEX(icons!B:B, MATCH(A16,icons!A:A,0)),"")} -> https://blogger.googleusercontent.com/img/b/R29vZ2xl/AVvXsEjl4gJnZqQz-Wz4S_mjixZgRnvCTYbIzoYs34k0e5qslitovNsUJbX8owsXEISCuHSFYbZ09JrRBr6sH3QaUm9TltnTRlyFnl9W2TW2T1iIMnB9MKpoMWMpZi0lY0uBU5cSYKi5i2Uy0XQucH0orBc8QCDtkRIkSB6SnaBhBmeB-SeGFVUiKF93/s510/itau%20logo%20novo%201.jpg
A17: AA - Santander | B17: 11182.07 | C17: 45940 | D17: Ivana | E17: =IFERROR(IF(C17<>"",TEXT(C17, "yyyy-mm"),""),"") -> 2025-10 | F17: {=IF(A17<>"",INDEX(icons!B:B, MATCH(A17,icons!A:A,0)),"")} -> https://assets.hgbrasil.com/finance/companies/big/santander-br.png
A18: Unq - Santander | B18: 8670.01 | C18: 45951 | D18: Ivana | E18: =IFERROR(IF(C18<>"",TEXT(C18, "yyyy-mm"),""),"") -> 2025-10 | F18: {=IF(A18<>"",INDEX(icons!B:B, MATCH(A18,icons!A:A,0)),"")} -> https://assets.hgbrasil.com/finance/companies/big/santander-br.png
A19: Elo | B19: =87.68 -> 87.68 | C19: 45940 | D19: Ivana | E19: =IFERROR(IF(C19<>"",TEXT(C19, "yyyy-mm"),""),"") -> 2025-10 | F19: {=IF(A19<>"",INDEX(icons!B:B, MATCH(A19,icons!A:A,0)),"")} -> https://www.publicitarioscriativos.com/wp-content/uploads/2024/05/442415684_844179061088736_7389654490654112245_n.jpg
A20: Azul - Itau | B20: 4736 | C20: 45951 | D20: Ivana | E20: =IFERROR(IF(C20<>"",TEXT(C20, "yyyy-mm"),""),"") -> 2025-10 | F20: {=IF(A20<>"",INDEX(icons!B:B, MATCH(A20,icons!A:A,0)),"")} -> https://blogger.googleusercontent.com/img/b/R29vZ2xl/AVvXsEjl4gJnZqQz-Wz4S_mjixZgRnvCTYbIzoYs34k0e5qslitovNsUJbX8owsXEISCuHSFYbZ09JrRBr6sH3QaUm9TltnTRlyFnl9W2TW2T1iIMnB9MKpoMWMpZi0lY0uBU5cSYKi5i2Uy0XQucH0orBc8QCDtkRIkSB6SnaBhBmeB-SeGFVUiKF93/s510/itau%20logo%20novo%201.jpg
A21: AA - Santander | B21: 15547.42 | C21: 45971 | D21: Ivana | E21: =IFERROR(IF(C21<>"",TEXT(C21, "yyyy-mm"),""),"") -> 2025-11 | F21: {=IF(A21<>"",INDEX(icons!B:B, MATCH(A21,icons!A:A,0)),"")} -> https://assets.hgbrasil.com/finance/companies/big/santander-br.png
A22: Unq - Santander | B22: 4323.03 | C22: 45982 | D22: Ivana | E22: =IFERROR(IF(C22<>"",TEXT(C22, "yyyy-mm"),""),"") -> 2025-11 | F22: {=IF(A22<>"",INDEX(icons!B:B, MATCH(A22,icons!A:A,0)),"")} -> https://assets.hgbrasil.com/finance/companies/big/santander-br.png
A23: Azul - Itau | B23: 11665.86 | C23: 45982 | D23: Ivana | E23: =IFERROR(IF(C23<>"",TEXT(C23, "yyyy-mm"),""),"") -> 2025-11 | F23: {=IF(A23<>"",INDEX(icons!B:B, MATCH(A23,icons!A:A,0)),"")} -> https://blogger.googleusercontent.com/img/b/R29vZ2xl/AVvXsEjl4gJnZqQz-Wz4S_mjixZgRnvCTYbIzoYs34k0e5qslitovNsUJbX8owsXEISCuHSFYbZ09JrRBr6sH3QaUm9TltnTRlyFnl9W2TW2T1iIMnB9MKpoMWMpZi0lY0uBU5cSYKi5i2Uy0XQucH0orBc8QCDtkRIkSB6SnaBhBmeB-SeGFVUiKF93/s510/itau%20logo%20novo%201.jpg
A24: AA - Santander | B24: 17505.85 | C24: 46001 | D24: Ivana | E24: =IFERROR(IF(C24<>"",TEXT(C24, "yyyy-mm"),""),"") -> 2025-12 | F24: {=IF(A24<>"",INDEX(icons!B:B, MATCH(A24,icons!A:A,0)),"")} -> https://assets.hgbrasil.com/finance/companies/big/santander-br.png
A25: Unq - Santander | B25: 926.95 | C25: 46012 | D25: Ivana | E25: =IFERROR(IF(C25<>"",TEXT(C25, "yyyy-mm"),""),"") -> 2025-12 | F25: {=IF(A25<>"",INDEX(icons!B:B, MATCH(A25,icons!A:A,0)),"")} -> https://assets.hgbrasil.com/finance/companies/big/santander-br.png
A26: Azul - Itau | B26: 6585.51 | C26: 46012 | D26: Ivana | E26: =IFERROR(IF(C26<>"",TEXT(C26, "yyyy-mm"),""),"") -> 2025-12 | F26: {=IF(A26<>"",INDEX(icons!B:B, MATCH(A26,icons!A:A,0)),"")} -> https://blogger.googleusercontent.com/img/b/R29vZ2xl/AVvXsEjl4gJnZqQz-Wz4S_mjixZgRnvCTYbIzoYs34k0e5qslitovNsUJbX8owsXEISCuHSFYbZ09JrRBr6sH3QaUm9TltnTRlyFnl9W2TW2T1iIMnB9MKpoMWMpZi0lY0uBU5cSYKi5i2Uy0XQucH0orBc8QCDtkRIkSB6SnaBhBmeB-SeGFVUiKF93/s510/itau%20logo%20novo%201.jpg
A27: AA - Santander | B27: 20708.33 | C27: 46032 | D27: Ivana | E27: =IFERROR(IF(C27<>"",TEXT(C27, "yyyy-mm"),""),"") -> 2026-01 | F27: {=IF(A27<>"",INDEX(icons!B:B, MATCH(A27,icons!A:A,0)),"")} -> https://assets.hgbrasil.com/finance/companies/big/santander-br.png
A28: Unq - Santander | B28: 1539.08 | C28: 46043 | D28: Ivana | E28: =IFERROR(IF(C28<>"",TEXT(C28, "yyyy-mm"),""),"") -> 2026-01 | F28: {=IF(A28<>"",INDEX(icons!B:B, MATCH(A28,icons!A:A,0)),"")} -> https://assets.hgbrasil.com/finance/companies/big/santander-br.png
A29: Azul - Itau | B29: 23594.17 | C29: 46043 | D29: Ivana | E29: =IFERROR(IF(C29<>"",TEXT(C29, "yyyy-mm"),""),"") -> 2026-01 | F29: {=IF(A29<>"",INDEX(icons!B:B, MATCH(A29,icons!A:A,0)),"")} -> https://blogger.googleusercontent.com/img/b/R29vZ2xl/AVvXsEjl4gJnZqQz-Wz4S_mjixZgRnvCTYbIzoYs34k0e5qslitovNsUJbX8owsXEISCuHSFYbZ09JrRBr6sH3QaUm9TltnTRlyFnl9W2TW2T1iIMnB9MKpoMWMpZi0lY0uBU5cSYKi5i2Uy0XQucH0orBc8QCDtkRIkSB6SnaBhBmeB-SeGFVUiKF93/s510/itau%20logo%20novo%201.jpg
A30: AA - Santander | B30: 21243.57 | C30: 46063 | D30: Ivana | E30: =IFERROR(IF(C30<>"",TEXT(C30, "yyyy-mm"),""),"") -> 2026-02 | F30: {=IF(A30<>"",INDEX(icons!B:B, MATCH(A30,icons!A:A,0)),"")} -> https://assets.hgbrasil.com/finance/companies/big/santander-br.png
A31: Unq - Santander | B31: 1264.14 | C31: 46074 | D31: Ivana | E31: =IFERROR(IF(C31<>"",TEXT(C31, "yyyy-mm"),""),"") -> 2026-02 | F31: {=IF(A31<>"",INDEX(icons!B:B, MATCH(A31,icons!A:A,0)),"")} -> https://assets.hgbrasil.com/finance/companies/big/santander-br.png
... A40: AA - Santander | B40: 3523 | C40: 46183 | D40: Ivana | E40: =IFERROR(IF(C40<>"",TEXT(C40, "yyyy-mm"),""),"") -> 2026-06 | F40: {=IF(A40<>"",INDEX(icons!B:B, MATCH(A40,icons!A:A,0)),"")} -> https://assets.hgbrasil.com/finance/companies/big/santander-br.png
A41: =cartoes!A2 -> BTG | B41: 390.38 | C41: 45943 | D41: Samuel | E41: =IFERROR(IF(C41<>"",TEXT(C41, "yyyy-mm"),""),"") -> 2025-10 | F41: {=IF(A41<>"",INDEX(icons!B:B, MATCH(A41,icons!A:A,0)),"")} -> https://play-lh.googleusercontent.com/O5Z9jsv79WTfdd37TFPyIwAQjNotIZTTEC6sOXaD3_2IXrMjtOI2ZnqReOicI3TgmqI
A42: =cartoes!A2 -> BTG | B42: 390.38 | C42: 45974 | D42: Samuel | E42: =IFERROR(IF(C42<>"",TEXT(C42, "yyyy-mm"),""),"") -> 2025-11 | F42: {=IF(A42<>"",INDEX(icons!B:B, MATCH(A42,icons!A:A,0)),"")} -> https://play-lh.googleusercontent.com/O5Z9jsv79WTfdd37TFPyIwAQjNotIZTTEC6sOXaD3_2IXrMjtOI2ZnqReOicI3TgmqI
A43: BTG | B43: 24.9 | C43: 46004 | D43: Samuel | E43: =IFERROR(IF(C43<>"",TEXT(C43, "yyyy-mm"),""),"") -> 2025-12 | F43: {=IF(A43<>"",INDEX(cartoes!E:E, MATCH(A43,cartoes!A:A,0)),"")} -> https://play-lh.googleusercontent.com/O5Z9jsv79WTfdd37TFPyIwAQjNotIZTTEC6sOXaD3_2IXrMjtOI2ZnqReOicI3TgmqI
A44: BTG | B44: 424.89 | C44: 46035 | D44: Samuel | E44: =IFERROR(IF(C44<>"",TEXT(C44, "yyyy-mm"),""),"") -> 2026-01 | F44: {=IF(A44<>"",INDEX(cartoes!E:E, MATCH(A44,cartoes!A:A,0)),"")} -> https://play-lh.googleusercontent.com/O5Z9jsv79WTfdd37TFPyIwAQjNotIZTTEC6sOXaD3_2IXrMjtOI2ZnqReOicI3TgmqI
A45: BTG | B45: 397.99 | C45: 46066 | D45: Samuel | E45: =IFERROR(IF(C45<>"",TEXT(C45, "yyyy-mm"),""),"") -> 2026-02 | F45: {=IF(A45<>"",INDEX(cartoes!E:E, MATCH(A45,cartoes!A:A,0)),"")} -> https://play-lh.googleusercontent.com/O5Z9jsv79WTfdd37TFPyIwAQjNotIZTTEC6sOXaD3_2IXrMjtOI2ZnqReOicI3TgmqI
A46: BTG | B46: 85.96 | C46: 46094 | D46: Samuel | E46: =IFERROR(IF(C46<>"",TEXT(C46, "yyyy-mm"),""),"") -> 2026-03 | F46: {=IF(A46<>"",INDEX(cartoes!E:E, MATCH(A46,cartoes!A:A,0)),"")} -> https://play-lh.googleusercontent.com/O5Z9jsv79WTfdd37TFPyIwAQjNotIZTTEC6sOXaD3_2IXrMjtOI2ZnqReOicI3TgmqI
A47: BTG | B47: 919.19 | C47: 46125 | D47: Samuel | E47: =IFERROR(IF(C47<>"",TEXT(C47, "yyyy-mm"),""),"") -> 2026-04 | F47: {=IF(A47<>"",INDEX(cartoes!E:E, MATCH(A47,cartoes!A:A,0)),"")} -> https://play-lh.googleusercontent.com/O5Z9jsv79WTfdd37TFPyIwAQjNotIZTTEC6sOXaD3_2IXrMjtOI2ZnqReOicI3TgmqI
A48: AA - Santander | B48: 7938 | C48: 46213 | D48: Ivana | E48: =IFERROR(IF(C48<>"",TEXT(C48, "yyyy-mm"),""),"") -> 2026-07 | F48: {=IF(A48<>"",INDEX(cartoes!E:E, MATCH(A48,cartoes!A:A,0)),"")} -> https://assets.hgbrasil.com/finance/companies/big/santander-br.png
...

Sheet despesas_recorrentes
A1: Despesa | B1: Valor | C1: Prazo | D1: Responsável
A2: Financiamento Caixa | B2: 17903 | C2: 58430 | D2: Ivana
A3: Condomínio | B3: 1150 | C3: 51498 | D3: Samuel
A4: Telefonia | B4: 260 | D4: Samuel
A5: Salário Jackie | B5: 3400 | D5: Ivana
A6: Nutrição | B6: 500 | D6: Samuel
A7: Caesb | B7: 400 | D7: Ivana
A8: Neoenergia | B8: 150 | D8: Ivana
A9: Natação | B9: 400 | D9: Ivana
A10: Ginastica Olimpica | B10: 500 | D10: Ivana
A11: Piscineiro | B11: 250 | D11: Ivana
A12: Gastos cartão | B12: 8000 | D12: Ivana
A13: Jardineiro | B13: 500 | D13: Samuel
A14: Financiamento Jaque | B14: 600 | D14: Samuel

Sheet receitas_recorrentes
A1: Receita | B1: Valor | C1: Responsável | D1: Dia Recebimento
A2: Salário Ivana | B2: 33200 | C2: Ivana | D2: 20
A3: Salário Samuel | B3: 22499 | C3: Samuel | D3: 1
A4: Investimentos | B4: 500 | C4: Samuel | D4: 10
A5: Alimentação Samuel | B5: 720 | C5: Samuel | D5: 1

Sheet receitas_pontuais
A1: Receita | B1: Valor | C1: Data | D1: Responsável | E1: chave_ano_mes
A2: Férias Ivana | B2: =B5/3 -> 7499.6667 | C2: 46193 | D2: Ivana | E2: =IFERROR(IF(C2<>"",TEXT(C2, "yyyy-mm"),""),"") -> 2026-06
A3: Férias Samuel | B3: =B4/3 -> 8600 | C3: 45809 | D3: Samuel | E3: =IFERROR(IF(C3<>"",TEXT(C3, "yyyy-mm"),""),"") -> 2025-06
A4: 13o Ivana | B4: 25800 | C4: 46346 | D4: Ivana | E4: =IFERROR(IF(C4<>"",TEXT(C4, "yyyy-mm"),""),"") -> 2026-11
A5: 13o Samuel | B5: =receitas_recorrentes!B3 -> 22499 | C5: 46357 | D5: Samuel | E5: =IFERROR(IF(C5<>"",TEXT(C5, "yyyy-mm"),""),"") -> 2026-12
A6: Restituição IR | B6: 5988 | C6: 46264 | D6: Ivana | E6: =IFERROR(IF(C6<>"",TEXT(C6, "yyyy-mm"),""),"") -> 2026-08
A7: Restituição IR | B7: 2947.08 | C7: 46203 | D7: Samuel | E7: =IFERROR(IF(C7<>"",TEXT(C7, "yyyy-mm"),""),"") -> 2026-06
E10: =IFERROR(IF(C10<>"",TEXT(C10, "yyyy-mm"),""),"")
E11: =IFERROR(IF(C11<>"",TEXT(C11, "yyyy-mm"),""),"")
E12: =IFERROR(IF(C12<>"",TEXT(C12, "yyyy-mm"),""),"")
E13: =IFERROR(IF(C13<>"",TEXT(C13, "yyyy-mm"),""),"")
E14: =IFERROR(IF(C14<>"",TEXT(C14, "yyyy-mm"),""),"")
E15: =IFERROR(IF(C15<>"",TEXT(C15, "yyyy-mm"),""),"")
E16: =IFERROR(IF(C16<>"",TEXT(C16, "yyyy-mm"),""),"")
E17: =IFERROR(IF(C17<>"",TEXT(C17, "yyyy-mm"),""),"")
E18: =IFERROR(IF(C18<>"",TEXT(C18, "yyyy-mm"),""),"")
E19: =IFERROR(IF(C19<>"",TEXT(C19, "yyyy-mm"),""),"")
E20: =IFERROR(IF(C20<>"",TEXT(C20, "yyyy-mm"),""),"")
E21: =IFERROR(IF(C21<>"",TEXT(C21, "yyyy-mm"),""),"")
... E30: =IFERROR(IF(C30<>"",TEXT(C30, "yyyy-mm"),""),"")

Sheet investimento
A1: local | B1: posicao_atual | C1: instituicao | D1: Data | E1: Responsável | F1: chave_ano_mes
A2: Fundos de Investimento | B2: 7676.63 | C2: BTG | D2: 46201 | E2: Samuel | F2: =IFERROR(IF(D2<>"",TEXT(D2, "yyyy-mm"),""),"") -> 2026-06
A3: Renda Fixa | B3: 0 | C3: BTG | D3: 46201 | E3: Samuel | F3: =IFERROR(IF(D3<>"",TEXT(D3, "yyyy-mm"),""),"") -> 2026-06
A4: Renda Variável | B4: 73654.97 | C4: BTG | D4: 46201 | E4: Samuel | F4: =IFERROR(IF(D4<>"",TEXT(D4, "yyyy-mm"),""),"") -> 2026-06
A5: Conta investimento BTG | B5: 1023.16 | C5: BTG | D5: 46201 | E5: Samuel | F5: =IFERROR(IF(D5<>"",TEXT(D5, "yyyy-mm"),""),"") -> 2026-06
A6: Renda Fixa | B6: 45407.14 | C6: BTG | D6: 46201 | E6: Ivana | F6: =IFERROR(IF(D6<>"",TEXT(D6, "yyyy-mm"),""),"") -> 2026-06
A7: Fundos de Investimento | B7: 4594.75 | C7: BTG | D7: 46201 | E7: Ivana | F7: =IFERROR(IF(D7<>"",TEXT(D7, "yyyy-mm"),""),"") -> 2026-06
A8: Renda Variável | B8: 418.39 | C8: BTG | D8: 46201 | E8: Ivana | F8: =IFERROR(IF(D8<>"",TEXT(D8, "yyyy-mm"),""),"") -> 2026-06
A9: Conta investimento BTG | B9: 269.58 | C9: BTG | D9: 46201 | E9: Ivana | F9: =IFERROR(IF(D9<>"",TEXT(D9, "yyyy-mm"),""),"") -> 2026-06
F10: =IFERROR(IF(D10<>"",TEXT(D10, "yyyy-mm"),""),"")
F11: =IFERROR(IF(D11<>"",TEXT(D11, "yyyy-mm"),""),"")
F12: =IFERROR(IF(D12<>"",TEXT(D12, "yyyy-mm"),""),"")
F13: =IFERROR(IF(D13<>"",TEXT(D13, "yyyy-mm"),""),"")
F14: =IFERROR(IF(D14<>"",TEXT(D14, "yyyy-mm"),""),"")
F15: =IFERROR(IF(D15<>"",TEXT(D15, "yyyy-mm"),""),"")
F16: =IFERROR(IF(D16<>"",TEXT(D16, "yyyy-mm"),""),"")
F17: =IFERROR(IF(D17<>"",TEXT(D17, "yyyy-mm"),""),"")
F18: =IFERROR(IF(D18<>"",TEXT(D18, "yyyy-mm"),""),"")
F19: =IFERROR(IF(D19<>"",TEXT(D19, "yyyy-mm"),""),"")
F20: =IFERROR(IF(D20<>"",TEXT(D20, "yyyy-mm"),""),"")
F21: =IFERROR(IF(D21<>"",TEXT(D21, "yyyy-mm"),""),"")
F22: =IFERROR(IF(D22<>"",TEXT(D22, "yyyy-mm"),""),"")

Sheet saldo
A1: Mês | B1: chave_ano_mes | C1: Despesas | D1: Receitas | E1: Saldo corrente | F1: Saldo conta | G1: Previsões | H1: Acumulado Previsões | I1: Saldo mensal | J1: Aporte metas | K1: Saldo mensal aportes | L1: Acumulado aporte | M1: Saldo total
A2: 45901 | B2: =IFERROR(IF(A2<>"",TEXT(A2, "yyyy-mm"),""),"") -> 2025-09 | C2: =SUMIF(despesas_recorrentes!C:C, ">="&A2,despesas_recorrentes!B:B) +SUMIF(despesas_recorrentes!C:C, "",despesas_recorrentes!B:B) -despesas_recorrentes!$B$12 +IF(SUMIF(gasto_cartao!E:E,saldo!B2,gasto_cartao!B:B)>despesas_recorrentes!$B$12, SUMIF(gasto_cartao!E:E,saldo!B2,gasto_cartao!B:B),despesas_recorrentes!$B$12) -> 63389.75 | D2: =SUM(receitas_recorrentes!B:B)+SUMIF(receitas_pontuais!E:E,B2,receitas_pontuais!B:B) -> 56919 | E2: =D2-C2 -> -6470.75 | F2: =IFERROR(SUMIF(contas!G:G, B2, contas!B:B),0) -> 0 | G2: =SUMIFS(previsoes!D:D, previsoes!E:E, "<=" & EOMONTH(DATEVALUE(B2&"-01"),0), previsoes!F:F, ">=" & DATEVALUE(B2&"-01")) -> 0 | H2: =G2 -> 0 | I2: =E2-G2 -> -6470.75 | J2: =IF(A2<>"",SUMIFS(metas!N:N, metas!E:E, ">=" & DATEVALUE(B2&"-01"),metas!D:D, "<=" & DATEVALUE(B2&"-01")),"") -> 15092.725 | K2: =IF(I2>0, I2-J2,-J2) -> -15092.725 | L2: =K2 -> -15092.725 | M2: =IF(A2<>"",SUM(investimento!B:B)+I2,"") -> 126573.87
A3: 45931 | B3: =IFERROR(IF(A3<>"",TEXT(A3, "yyyy-mm"),""),"") -> 2025-10 | C3: =SUMIF(despesas_recorrentes!C:C, ">="&A3,despesas_recorrentes!B:B) +SUMIF(despesas_recorrentes!C:C, "",despesas_recorrentes!B:B) -despesas_recorrentes!$B$12 +IF(SUMIF(gasto_cartao!E:E,saldo!B3,gasto_cartao!B:B)>despesas_recorrentes!$B$12, SUMIF(gasto_cartao!E:E,saldo!B3,gasto_cartao!B:B),despesas_recorrentes!$B$12) -> 51079.14 | D3: =SUM(receitas_recorrentes!B:B)+SUMIF(receitas_pontuais!E:E,B3,receitas_pontuais!B:B) -> 56919 | E3: =D3-C3 -> 5839.86 | F3: =IFERROR(SUMIF(contas!G:G, B3, contas!B:B),0) -> 0 | G3: =SUMIFS(previsoes!D:D, previsoes!E:E, "<=" & EOMONTH(DATEVALUE(B3&"-01"),0), previsoes!F:F, ">=" & DATEVALUE(B3&"-01")) -> 0 | H3: =H2+G3 -> 0 | I3: =E3-G3 -> 5839.86 | J3: =IF(A3<>"",SUMIFS(metas!N:N, metas!E:E, ">=" & DATEVALUE(B3&"-01"),metas!D:D, "<=" & DATEVALUE(B3&"-01")),"") -> 15092.725 | K3: =IF(I3>0, I3-J3,-J3) -> -9252.8652 | L3: =K3+L2 -> -24345.59 | M3: =IF(A3<>"",IF(COUNTIF(investimento!F:F, B3) > 0, SUM(investimento!B:B)+I3, M2+I3),"") -> 132413.73
A4: 45962 | B4: =IFERROR(IF(A4<>"",TEXT(A4, "yyyy-mm"),""),"") -> 2025-11 | C4: =SUMIF(despesas_recorrentes!C:C, ">="&A4,despesas_recorrentes!B:B) +SUMIF(despesas_recorrentes!C:C, "",despesas_recorrentes!B:B) -despesas_recorrentes!$B$12 +IF(SUMIF(gasto_cartao!E:E,saldo!B4,gasto_cartao!B:B)>despesas_recorrentes!$B$12, SUMIF(gasto_cartao!E:E,saldo!B4,gasto_cartao!B:B),despesas_recorrentes!$B$12) -> 57939.69 | D4: =SUM(receitas_recorrentes!B:B)+SUMIF(receitas_pontuais!E:E,B4,receitas_pontuais!B:B) -> 56919 | E4: =D4-C4 -> -1020.69 | F4: =IFERROR(SUMIF(contas!G:G, B4, contas!B:B),0) -> 0 | G4: =SUMIFS(previsoes!D:D, previsoes!E:E, "<=" & EOMONTH(DATEVALUE(B4&"-01"),0), previsoes!F:F, ">=" & DATEVALUE(B4&"-01")) -> 0 | H4: =H3+G4 -> 0 | I4: =E4-G4 -> -1020.69 | J4: =IF(A4<>"",SUMIFS(metas!N:N, metas!E:E, ">=" & DATEVALUE(B4&"-01"),metas!D:D, "<=" & DATEVALUE(B4&"-01")),"") -> 15092.725 | K4: =IF(I4>0, I4-J4,-J4) -> -15092.725 | L4: =K4+L3 -> -39438.316 | M4: =IF(A4<>"",IF(COUNTIF(investimento!F:F, B4) > 0, SUM(investimento!B:B)+I4, M3+I4),"") -> 131393.04
A5: 45992 | B5: =IFERROR(IF(A5<>"",TEXT(A5, "yyyy-mm"),""),"") -> 2025-12 | C5: =SUMIF(despesas_recorrentes!C:C, ">="&A5,despesas_recorrentes!B:B) +SUMIF(despesas_recorrentes!C:C, "",despesas_recorrentes!B:B) -despesas_recorrentes!$B$12 +IF(SUMIF(gasto_cartao!E:E,saldo!B5,gasto_cartao!B:B)>despesas_recorrentes!$B$12, SUMIF(gasto_cartao!E:E,saldo!B5,gasto_cartao!B:B),despesas_recorrentes!$B$12) -> 51056.21 | D5: =SUM(receitas_recorrentes!B:B)+SUMIF(receitas_pontuais!E:E,B5,receitas_pontuais!B:B) -> 56919 | E5: =D5-C5 -> 5862.79 | F5: =IFERROR(SUMIF(contas!G:G, B5, contas!B:B),0) -> 0 | G5: =SUMIFS(previsoes!D:D, previsoes!E:E, "<=" & EOMONTH(DATEVALUE(B5&"-01"),0), previsoes!F:F, ">=" & DATEVALUE(B5&"-01")) -> 0 | H5: =H4+G5 -> 0 | I5: =E5-G5 -> 5862.79 | J5: =IF(A5<>"",SUMIFS(metas!N:N, metas!E:E, ">=" & DATEVALUE(B5&"-01"),metas!D:D, "<=" & DATEVALUE(B5&"-01")),"") -> 15092.725 | K5: =IF(I5>0, I5-J5,-J5) -> -9229.9352 | L5: =K5+L4 -> -48668.251 | M5: =IF(A5<>"",IF(COUNTIF(investimento!F:F, B5) > 0, SUM(investimento!B:B)+I5, M4+I5),"") -> 137255.83
A6: 46023 | B6: =IFERROR(IF(A6<>"",TEXT(A6, "yyyy-mm"),""),"") -> 2026-01 | C6: =SUMIF(despesas_recorrentes!C:C, ">="&A6,despesas_recorrentes!B:B) +SUMIF(despesas_recorrentes!C:C, "",despesas_recorrentes!B:B) -despesas_recorrentes!$B$12 +IF(SUMIF(gasto_cartao!E:E,saldo!B6,gasto_cartao!B:B)>despesas_recorrentes!$B$12, SUMIF(gasto_cartao!E:E,saldo!B6,gasto_cartao!B:B),despesas_recorrentes!$B$12) -> 72279.47 | D6: =SUM(receitas_recorrentes!B:B)+SUMIF(receitas_pontuais!E:E,B6,receitas_pontuais!B:B) -> 56919 | E6: =D6-C6 -> -15360.47 | F6: =IFERROR(SUMIF(contas!G:G, B6, contas!B:B),0) -> 9450 | G6: =SUMIFS(previsoes!D:D, previsoes!E:E, "<=" & EOMONTH(DATEVALUE(B6&"-01"),0), previsoes!F:F, ">=" & DATEVALUE(B6&"-01")) -> 0 | H6: =H5+G6 -> 0 | I6: =E6-G6 -> -15360.47 | J6: =IF(A6<>"",SUMIFS(metas!N:N, metas!E:E, ">=" & DATEVALUE(B6&"-01"),metas!D:D, "<=" & DATEVALUE(B6&"-01")),"") -> 15092.725 | K6: =IF(I6>0, I6-J6,-J6) -> -15092.725 | L6: =K6+L5 -> -63760.976 | M6: =IF(A6<>"",IF(COUNTIF(investimento!F:F, B6) > 0, SUM(investimento!B:B)+I6, M5+I6),"") -> 121895.36
A7: 46054 | B7: =IFERROR(IF(A7<>"",TEXT(A7, "yyyy-mm"),""),"") -> 2026-02 | C7: =SUMIF(despesas_recorrentes!C:C, ">="&A7,despesas_recorrentes!B:B) +SUMIF(despesas_recorrentes!C:C, "",despesas_recorrentes!B:B) -despesas_recorrentes!$B$12 +IF(SUMIF(gasto_cartao!E:E,saldo!B7,gasto_cartao!B:B)>despesas_recorrentes!$B$12, SUMIF(gasto_cartao!E:E,saldo!B7,gasto_cartao!B:B),despesas_recorrentes!$B$12) -> 65255.53 | D7: =SUM(receitas_recorrentes!B:B)+SUMIF(receitas_pontuais!E:E,B7,receitas_pontuais!B:B) -> 56919 | E7: =D7-C7 -> -8336.53 | F7: =IFERROR(SUMIF(contas!G:G, B7, contas!B:B),0) -> 0 | G7: =SUMIFS(previsoes!D:D, previsoes!E:E, "<=" & EOMONTH(DATEVALUE(B7&"-01"),0), previsoes!F:F, ">=" & DATEVALUE(B7&"-01")) -> 0 | H7: =H6+G7 -> 0 | I7: =E7-G7 -> -8336.53 | J7: =IF(A7<>"",SUMIFS(metas!N:N, metas!E:E, ">=" & DATEVALUE(B7&"-01"),metas!D:D, "<=" & DATEVALUE(B7&"-01")),"") -> 15092.725 | K7: =IF(I7>0, I7-J7,-J7) -> -15092.725 | L7: =K7+L6 -> -78853.701 | M7: =IF(A7<>"",IF(COUNTIF(investimento!F:F, B7) > 0, SUM(investimento!B:B)+I7, M6+I7),"") -> 113558.83
A8: 46082 | B8: =IFERROR(IF(A8<>"",TEXT(A8, "yyyy-mm"),""),"") -> 2026-03 | C8: =SUMIF(despesas_recorrentes!C:C, ">="&A8,despesas_recorrentes!B:B) +SUMIF(despesas_recorrentes!C:C, "",despesas_recorrentes!B:B) -despesas_recorrentes!$B$12 +IF(SUMIF(gasto_cartao!E:E,saldo!B8,gasto_cartao!B:B)>despesas_recorrentes!$B$12, SUMIF(gasto_cartao!E:E,saldo!B8,gasto_cartao!B:B),despesas_recorrentes!$B$12) -> 57908.03 | D8: =SUM(receitas_recorrentes!B:B)+SUMIF(receitas_pontuais!E:E,B8,receitas_pontuais!B:B) -> 56919 | E8: =D8-C8 -> -989.03 | F8: =IFERROR(SUMIF(contas!G:G, B8, contas!B:B),0) -> 0 | G8: =SUMIFS(previsoes!D:D, previsoes!E:E, "<=" & EOMONTH(DATEVALUE(B8&"-01"),0), previsoes!F:F, ">=" & DATEVALUE(B8&"-01")) -> 0 | H8: =H7+G8 -> 0 | I8: =E8-G8 -> -989.03 | J8: =IF(A8<>"",SUMIFS(metas!N:N, metas!E:E, ">=" & DATEVALUE(B8&"-01"),metas!D:D, "<=" & DATEVALUE(B8&"-01")),"") -> 15092.725 | K8: =IF(I8>0, I8-J8,-J8) -> -15092.725 | L8: =K8+L7 -> -93946.427 | M8: =IF(A8<>"",IF(COUNTIF(investimento!F:F, B8) > 0, SUM(investimento!B:B)+I8, M7+I8),"") -> 112569.8
A9: 46113 | B9: =IFERROR(IF(A9<>"",TEXT(A9, "yyyy-mm"),""),"") -> 2026-04 | C9: =SUMIF(despesas_recorrentes!C:C, ">="&A9,despesas_recorrentes!B:B) +SUMIF(despesas_recorrentes!C:C, "",despesas_recorrentes!B:B) -despesas_recorrentes!$B$12 +IF(SUMIF(gasto_cartao!E:E,saldo!B9,gasto_cartao!B:B)>despesas_recorrentes!$B$12, SUMIF(gasto_cartao!E:E,saldo!B9,gasto_cartao!B:B),despesas_recorrentes!$B$12) -> 63350.36 | D9: =SUM(receitas_recorrentes!B:B)+SUMIF(receitas_pontuais!E:E,B9,receitas_pontuais!B:B) -> 56919 | E9: =D9-C9 -> -6431.36 | F9: =IFERROR(SUMIF(contas!G:G, B9, contas!B:B),0) -> 0 | G9: =SUMIFS(previsoes!D:D, previsoes!E:E, "<=" & EOMONTH(DATEVALUE(B9&"-01"),0), previsoes!F:F, ">=" & DATEVALUE(B9&"-01")) -> 0 | H9: =H8+G9 -> 0 | I9: =E9-G9 -> -6431.36 | J9: =IF(A9<>"",SUMIFS(metas!N:N, metas!E:E, ">=" & DATEVALUE(B9&"-01"),metas!D:D, "<=" & DATEVALUE(B9&"-01")),"") -> 15092.725 | K9: =IF(I9>0, I9-J9,-J9) -> -15092.725 | L9: =K9+L8 -> -109039.15 | M9: =IF(A9<>"",IF(COUNTIF(investimento!F:F, B9) > 0, SUM(investimento!B:B)+I9, M8+I9),"") -> 106138.44
A10: 46143 | B10: =IFERROR(IF(A10<>"",TEXT(A10, "yyyy-mm"),""),"") -> 2026-05 | C10: =SUMIF(despesas_recorrentes!C:C, ">="&A10,despesas_recorrentes!B:B) +SUMIF(despesas_recorrentes!C:C, "",despesas_recorrentes!B:B) -despesas_recorrentes!$B$12 +IF(SUMIF(gasto_cartao!E:E,saldo!B10,gasto_cartao!B:B)>despesas_recorrentes!$B$12, SUMIF(gasto_cartao!E:E,saldo!B10,gasto_cartao!B:B),despesas_recorrentes!$B$12) -> 57251 | D10: =SUM(receitas_recorrentes!B:B)+SUMIF(receitas_pontuais!E:E,B10,receitas_pontuais!B:B) -> 56919 | E10: =D10-C10 -> -332 | F10: =IFERROR(SUMIF(contas!G:G, B10, contas!B:B),0) -> 0 | G10: =SUMIFS(previsoes!D:D, previsoes!E:E, "<=" & EOMONTH(DATEVALUE(B10&"-01"),0), previsoes!F:F, ">=" & DATEVALUE(B10&"-01")) -> 0 | H10: =H9+G10 -> 0 | I10: =E10-G10 -> -332 | J10: =IF(A10<>"",SUMIFS(metas!N:N, metas!E:E, ">=" & DATEVALUE(B10&"-01"),metas!D:D, "<=" & DATEVALUE(B10&"-01")),"") -> 15092.725 | K10: =IF(I10>0, I10-J10,-J10) -> -15092.725 | L10: =K10+L9 -> -124131.88 | M10: =IF(A10<>"",IF(COUNTIF(investimento!F:F, B10) > 0, SUM(investimento!B:B)+I10, M9+I10),"") -> 105806.44
A11: 46174 | B11: =IFERROR(IF(A11<>"",TEXT(A11, "yyyy-mm"),""),"") -> 2026-06 | C11: =SUMIF(despesas_recorrentes!C:C, ">="&A11,despesas_recorrentes!B:B) +SUMIF(despesas_recorrentes!C:C, "",despesas_recorrentes!B:B) -despesas_recorrentes!$B$12 +IF(SUMIF(gasto_cartao!E:E,saldo!B11,gasto_cartao!B:B)>despesas_recorrentes!$B$12, SUMIF(gasto_cartao!E:E,saldo!B11,gasto_cartao!B:B),despesas_recorrentes!$B$12) -> 45856 | D11: =SUM(receitas_recorrentes!B:B)+SUMIF(receitas_pontuais!E:E,B11,receitas_pontuais!B:B) -> 67365.747 | E11: =D11-C11 -> 21509.747 | F11: =IFERROR(SUMIF(contas!G:G, B11, contas!B:B),0) -> 5321.81 | G11: =SUMIFS(previsoes!D:D, previsoes!E:E, "<=" & EOMONTH(DATEVALUE(B11&"-01"),0), previsoes!F:F, ">=" & DATEVALUE(B11&"-01")) -> 0 | H11: =H10+G11 -> 0 | I11: =E11-G11 -> 21509.747 | J11: =IF(A11<>"",SUMIFS(metas!N:N, metas!E:E, ">=" & DATEVALUE(B11&"-01"),metas!D:D, "<=" & DATEVALUE(B11&"-01")),"") -> 15092.725 | K11: =IF(I11>0, I11-J11,-J11) -> 6417.0214 | L11: =K11+L10 -> -117714.86 | M11: =IF(A11<>"",IF(COUNTIF(investimento!F:F, B11) > 0, SUM(investimento!B:B)+I11, M10+I11),"") -> 154554.37
A12: 46204 | B12: =IFERROR(IF(A12<>"",TEXT(A12, "yyyy-mm"),""),"") -> 2026-07 | C12: =SUMIF(despesas_recorrentes!C:C, ">="&A12,despesas_recorrentes!B:B) +SUMIF(despesas_recorrentes!C:C, "",despesas_recorrentes!B:B) -despesas_recorrentes!$B$12 +IF(SUMIF(gasto_cartao!E:E,saldo!B12,gasto_cartao!B:B)>despesas_recorrentes!$B$12, SUMIF(gasto_cartao!E:E,saldo!B12,gasto_cartao!B:B),despesas_recorrentes!$B$12) -> 55921.79 | D12: =SUM(receitas_recorrentes!B:B)+SUMIF(receitas_pontuais!E:E,B12,receitas_pontuais!B:B) -> 56919 | E12: =D12-C12 -> 997.21 | F12: =IFERROR(SUMIF(contas!G:G, B12, contas!B:B),0) -> 0 | G12: =SUMIFS(previsoes!D:D, previsoes!E:E, "<=" & EOMONTH(DATEVALUE(B12&"-01"),0), previsoes!F:F, ">=" & DATEVALUE(B12&"-01")) -> 0 | H12: =H11+G12 -> 0 | I12: =E12-G12 -> 997.21 | J12: =IF(A12<>"",SUMIFS(metas!N:N, metas!E:E, ">=" & DATEVALUE(B12&"-01"),metas!D:D, "<=" & DATEVALUE(B12&"-01")),"") -> 13759.733 | K12: =IF(I12>0, I12-J12,-J12) -> -12762.523 | L12: =K12+L11 -> -130477.38 | M12: =IF(A12<>"",IF(COUNTIF(investimento!F:F, B12) > 0, SUM(investimento!B:B)+I12, M11+I12),"") -> 155551.58
A13: 46235 | B13: =IFERROR(IF(A13<>"",TEXT(A13, "yyyy-mm"),""),"") -> 2026-08 | C13: =SUMIF(despesas_recorrentes!C:C, ">="&A13,despesas_recorrentes!B:B) +SUMIF(despesas_recorrentes!C:C, "",despesas_recorrentes!B:B) -despesas_recorrentes!$B$12 +IF(SUMIF(gasto_cartao!E:E,saldo!B13,gasto_cartao!B:B)>despesas_recorrentes!$B$12, SUMIF(gasto_cartao!E:E,saldo!B13,gasto_cartao!B:B),despesas_recorrentes!$B$12) -> 43338 | D13: =SUM(receitas_recorrentes!B:B)+SUMIF(receitas_pontuais!E:E,B13,receitas_pontuais!B:B) -> 62907 | E13: =D13-C13 -> 19569 | F13: =IFERROR(SUMIF(contas!G:G, B13, contas!B:B),0) -> 0 | G13: =SUMIFS(previsoes!D:D, previsoes!E:E, "<=" & EOMONTH(DATEVALUE(B13&"-01"),0), previsoes!F:F, ">=" & DATEVALUE(B13&"-01")) -> 5566.3425 | H13: =H12+G13 -> 5566.3425 | I13: =E13-G13 -> 14002.657 | J13: =IF(A13<>"",SUMIFS(metas!N:N, metas!E:E, ">=" & DATEVALUE(B13&"-01"),metas!D:D, "<=" & DATEVALUE(B13&"-01")),"") -> 13759.733 | K13: =IF(I13>0, I13-J13,-J13) -> 242.92456 | L13: =K13+L12 -> -130234.45 | M13: =IF(A13<>"",IF(COUNTIF(investimento!F:F, B13) > 0, SUM(investimento!B:B)+I13, M12+I13),"") -> 169554.23
A14: 46266 | B14: =IFERROR(IF(A14<>"",TEXT(A14, "yyyy-mm"),""),"") -> 2026-09 | C14: =SUMIF(despesas_recorrentes!C:C, ">="&A14,despesas_recorrentes!B:B) +SUMIF(despesas_recorrentes!C:C, "",despesas_recorrentes!B:B) -despesas_recorrentes!$B$12 +IF(SUMIF(gasto_cartao!E:E,saldo!B14,gasto_cartao!B:B)>despesas_recorrentes!$B$12, SUMIF(gasto_cartao!E:E,saldo!B14,gasto_cartao!B:B),despesas_recorrentes!$B$12) -> 39410 | D14: =SUM(receitas_recorrentes!B:B)+SUMIF(receitas_pontuais!E:E,B14,receitas_pontuais!B:B) -> 56919 | E14: =D14-C14 -> 17509 | F14: =IFERROR(SUMIF(contas!G:G, B14, contas!B:B),0) -> 0 | G14: =SUMIFS(previsoes!D:D, previsoes!E:E, "<=" & EOMONTH(DATEVALUE(B14&"-01"),0), previsoes!F:F, ">=" & DATEVALUE(B14&"-01")) -> 5566.3425 | H14: =H13+G14 -> 11132.685 | I14: =E14-G14 -> 11942.657 | J14: =IF(A14<>"",SUMIFS(metas!N:N, metas!E:E, ">=" & DATEVALUE(B14&"-01"),metas!D:D, "<=" & DATEVALUE(B14&"-01")),"") -> 13759.733 | K14: =IF(I14>0, I14-J14,-J14) -> -1817.0754 | L14: =K14+L13 -> -132051.53 | M14: =IF(A14<>"",IF(COUNTIF(investimento!F:F, B14) > 0, SUM(investimento!B:B)+I14, M13+I14),"") -> 181496.89
... A1001: 51050 | B1001: =IFERROR(IF(A1001<>"",TEXT(A1001, "yyyy-mm"),""),"") -> 2039-10 | C1001: =SUMIF(despesas_recorrentes!C:C, ">="&A1001,despesas_recorrentes!B:B) +SUMIF(despesas_recorrentes!C:C, "",despesas_recorrentes!B:B) -despesas_recorrentes!$B$12 +IF(SUMIF(gasto_cartao!E:E,saldo!B1001,gasto_cartao!B:B)>despesas_recorrentes!$B$12, SUMIF(gasto_cartao!E:E,saldo!B1001,gasto_cartao!B:B),despesas_recorrentes!$B$12) -> 34013 | D1001: =SUM(receitas_recorrentes!B:B)+SUMIF(receitas_pontuais!E:E,B1001,receitas_pontuais!B:B) -> 56919 | E1001: =D1001-C1001 -> 22906 | F1001: =IFERROR(SUMIF(contas!G:G, B1001, contas!B:B),0) -> 0 | G1001: =SUMIFS(previsoes!D:D, previsoes!E:E, "<=" & EOMONTH(DATEVALUE(B1001&"-01"),0), previsoes!F:F, ">=" & DATEVALUE(B1001&"-01")) -> 0 | H1001: =H1000+G1001 -> 160491.9 | I1001: =E1001-G1001 -> 22906 | J1001: =IF(A1001<>"",SUMIFS(metas!N:N, metas!E:E, ">=" & DATEVALUE(B1001&"-01"),metas!D:D, "<=" & DATEVALUE(B1001&"-01")),"") -> 3182.8139 | K1001: =IF(I1001>0, I1001-J1001,-J1001) -> 19723.186 | L1001: =K1001+L1000 -> 19087069 | M1001: =IF(A1001<>"",IF(COUNTIF(investimento!F:F, B1001) > 0, SUM(investimento!B:B)+I1001, M1000+I1001),"") -> 22688659

Sheet metas
A1: Meta | B1: Valor | C1: Peso | D1: Inicio | E1: Prazo | F1: chave_ano_mes | G1: Data atual | H1: Valor atual previa | I1: Peso zerado | J1: Peso atualizado | K1: Valor atual | L1: Valor faltante | M1: Meses restantes | N1: Aporte mensal | O1: Responsável | P1: Meta alcançada
A2: Reserva emergência | B2: 200000 | C2: 0.35 | D2: 45901 | E2: 46357 | F2: =IFERROR(IF(D2<>"",TEXT(D2, "yyyy-mm"),""),"") -> 2025-09 | G2: =IF(E2<>"",TODAY(),"") -> 46219 | H2: {=IF(A2<>"", IF( (INDEX(saldo!M:M, MATCH(TEXT(TODAY(),"yyyy-MM"),saldo!B:B,0))-SUM(reservas!B:B))*C2 > B2,B2, (INDEX(saldo!M:M, MATCH(TEXT(TODAY(),"yyyy-MM"),saldo!B:B,0))-SUM(reservas!B:B))*C2), "")} -> 54443.052 | I2: =IF(H2<>B2,C2,0) -> 0.35 | J2: =I2/SUM(I:I) -> 0.5 | K2: {=IF( I2<>0, (INDEX(saldo!M:M, MATCH(TEXT(TODAY(),"yyyy-MM"),saldo!B:B,0))-SUM(reservas!B:B)-SUMIF(I:I,"=0",H:H))*J2,H2)} -> 77775.788 | L2: =B2-K2 -> 122224.21 | M2: =IF(E2<>"",DATEDIF(D2,E2,"M"),"") -> 15 | N2: =IF(G2<>"",L2/M2,"") -> 8148.2808 | O2: Samuel | P2: =IF(K2<>"",IF(K2=B2,"TRUE", "FALSE"),"") -> FALSE
A3: Previdência | B3: 2000000 | C3: 0.05 | D3: 46419 | E3: 53114 | F3: =IFERROR(IF(D3<>"",TEXT(D3, "yyyy-mm"),""),"") -> 2027-02 | G3: =IF(E3<>"",TODAY(),"") -> 46219 | H3: {=IF(A3<>"", IF((INDEX(saldo!M:M, MATCH(TEXT(TODAY(),"yyyy-MM"),saldo!B:B,0))-SUM(reservas!B:B))*C3 > B3,B3,(INDEX(saldo!M:M, MATCH(TEXT(TODAY(),"yyyy-MM"),saldo!B:B,0))-SUM(reservas!B:B))*C3),"")} -> 7777.5788 | I3: =IF(H3<>B3,C3,0) -> 0.05 | J3: =I3/SUM(I:I) -> 0.071428571 | K3: {=IF( I3<>0, (INDEX(saldo!M:M, MATCH(TEXT(TODAY(),"yyyy-MM"),saldo!B:B,0))-SUM(reservas!B:B)-SUMIF(I:I,"=0",H:H))*J3,H3)} -> 11110.827 | L3: =B3-K3 -> 1988889.2 | M3: =IF(E3<>"",DATEDIF(D3,E3,"M"),"") -> 220 | N3: =-PMT(0.1/12, M3, 0, L3) -> 3182.8139 | O3: Samuel | P3: =IF(K3<>"",IF(K3=B3,"TRUE", "FALSE"),"") -> FALSE
A4: Viagem para China | B4: 60000 | C4: 0.3 | D4: 46204 | E4: 46357 | F4: =IFERROR(IF(D4<>"",TEXT(D4, "yyyy-mm"),""),"") -> 2026-07 | G4: =IF(E4<>"",TODAY(),"") -> 46219 | H4: {=IF(A4<>"", IF((INDEX(saldo!M:M, MATCH(TEXT(TODAY(),"yyyy-MM"),saldo!B:B,0))-SUM(reservas!B:B))*C4 > B4,B4,(INDEX(saldo!M:M, MATCH(TEXT(TODAY(),"yyyy-MM"),saldo!B:B,0))-SUM(reservas!B:B))*C4),"")} -> 46665.473 | I4: =IF(H4<>B4,C4,0) -> 0.3 | J4: =I4/SUM(I:I) -> 0.42857143 | K4: {=IF( I4<>0, (INDEX(saldo!M:M, MATCH(TEXT(TODAY(),"yyyy-MM"),saldo!B:B,0))-SUM(reservas!B:B)-SUMIF(I:I,"=0",H:H))*J4,H4)} -> 66664.961 | L4: =B4-K4 -> -6664.9614 | M4: =IF(E4<>"",DATEDIF(D4,E4,"M"),"") -> 5 | N4: =IF(G4<>"",L4/M4,"") -> -1332.9923 | O4: Ivana | P4: =IF(K4<>"",IF(K4=B4,"TRUE", "FALSE"),"") -> FALSE
A5: Carro Samuel | B5: 250000 | C5: 0 | D5: 45778 | E5: 46874 | F5: =IFERROR(IF(D5<>"",TEXT(D5, "yyyy-mm"),""),"") -> 2025-05 | G5: =IF(E5<>"",TODAY(),"") -> 46219 | H5: {=IF(A5<>"", IF((INDEX(saldo!M:M, MATCH(TEXT(TODAY(),"yyyy-MM"),saldo!B:B,0))-SUM(reservas!B:B))*C5 > B5,B5,(INDEX(saldo!M:M, MATCH(TEXT(TODAY(),"yyyy-MM"),saldo!B:B,0))-SUM(reservas!B:B))*C5),"")} -> 0 | I5: =IF(H5<>B5,C5,0) -> 0 | J5: =I5/SUM(I:I) -> 0 | K5: {=IF( I5<>0, (INDEX(saldo!M:M, MATCH(TEXT(TODAY(),"yyyy-MM"),saldo!B:B,0))-SUM(reservas!B:B)-SUMIF(I:I,"=0",H:H))*J5,H5)} -> 0 | L5: =B5-K5 -> 250000 | M5: =IF(E5<>"",DATEDIF(D5,E5,"M"),"") -> 36 | N5: =IF(G5<>"",L5/M5,"") -> 6944.4444 | O5: Samuel | P5: =IF(K5<>"",IF(K5=B5,"TRUE", "FALSE"),"") -> FALSE
F6: =IFERROR(IF(E6<>"",TEXT(E6, "yyyy-mm"),""),"") | G6: =IF(E6<>"",TODAY(),"") | M6: =IF(E6<>"",DATEDIF(G6,E6,"M"),"") | P6: =IF(K6<>"",IF(K6=B6,"TRUE", "FALSE"),"")
F7: =IFERROR(IF(E7<>"",TEXT(E7, "yyyy-mm"),""),"") | G7: =IF(E7<>"",TODAY(),"") | M7: =IF(E7<>"",DATEDIF(G7,E7,"M"),"") | N7: =IF(G7<>"",L7/M7,"") | P7: =IF(K7<>"",IF(K7=B7,"TRUE", "FALSE"),"")
F8: =IFERROR(IF(E8<>"",TEXT(E8, "yyyy-mm"),""),"") | G8: =IF(E8<>"",TODAY(),"") | M8: =IF(E8<>"",DATEDIF(G8,E8,"M"),"") | N8: =IF(G8<>"",L8/M8,"") | P8: =IF(K8<>"",IF(K8=B8,"TRUE", "FALSE"),"")
F9: =IFERROR(IF(E9<>"",TEXT(E9, "yyyy-mm"),""),"") | G9: =IF(E9<>"",TODAY(),"") | M9: =IF(E9<>"",DATEDIF(G9,E9,"M"),"") | N9: =IF(G9<>"",L9/M9,"") | P9: =IF(K9<>"",IF(K9=B9,"TRUE", "FALSE"),"")
F10: =IFERROR(IF(E10<>"",TEXT(E10, "yyyy-mm"),""),"") | G10: =IF(E10<>"",TODAY(),"") | M10: =IF(E10<>"",DATEDIF(G10,E10,"M"),"") | N10: =IF(G10<>"",L10/M10,"") | P10: =IF(K10<>"",IF(K10=B10,"TRUE", "FALSE"),"")
F11: =IFERROR(IF(E11<>"",TEXT(E11, "yyyy-mm"),""),"") | G11: =IF(E11<>"",TODAY(),"") | M11: =IF(E11<>"",DATEDIF(G11,E11,"M"),"") | N11: =IF(G11<>"",L11/M11,"") | P11: =IF(K11<>"",IF(K11=B11,"TRUE", "FALSE"),"")
F12: =IFERROR(IF(E12<>"",TEXT(E12, "yyyy-mm"),""),"") | G12: =IF(E12<>"",TODAY(),"") | M12: =IF(E12<>"",DATEDIF(G12,E12,"M"),"") | N12: =IF(G12<>"",L12/M12,"") | P12: =IF(K12<>"",IF(K12=B12,"TRUE", "FALSE"),"")
F13: =IFERROR(IF(E13<>"",TEXT(E13, "yyyy-mm"),""),"") | G13: =IF(E13<>"",TODAY(),"") | M13: =IF(E13<>"",DATEDIF(G13,E13,"M"),"") | N13: =IF(G13<>"",L13/M13,"") | P13: =IF(K13<>"",IF(K13=B13,"TRUE", "FALSE"),"")
F14: =IFERROR(IF(E14<>"",TEXT(E14, "yyyy-mm"),""),"") | G14: =IF(E14<>"",TODAY(),"") | M14: =IF(E14<>"",DATEDIF(G14,E14,"M"),"") | N14: =IF(G14<>"",L14/M14,"") | P14: =IF(K14<>"",IF(K14=B14,"TRUE", "FALSE"),"")
F15: =IFERROR(IF(E15<>"",TEXT(E15, "yyyy-mm"),""),"") | G15: =IF(E15<>"",TODAY(),"") | M15: =IF(E15<>"",DATEDIF(G15,E15,"M"),"") | N15: =IF(G15<>"",L15/M15,"") | P15: =IF(K15<>"",IF(K15=B15,"TRUE", "FALSE"),"")
F16: =IFERROR(IF(E16<>"",TEXT(E16, "yyyy-mm"),""),"") | G16: =IF(E16<>"",TODAY(),"") | N16: =IF(G16<>"",L16/M16,"") | P16: =IF(K16<>"",IF(K16=B16,"TRUE", "FALSE"),"")
F17: =IFERROR(IF(E17<>"",TEXT(E17, "yyyy-mm"),""),"") | N17: =IF(G17<>"",L17/M17,"") | P17: =IF(K17<>"",IF(K17=B17,"TRUE", "FALSE"),"")
N18: =IF(G18<>"",L18/M18,"")
N19: =IF(G19<>"",L19/M19,"")
N20: =IF(G20<>"",L20/M20,"")
N21: =IF(G21<>"",L21/M21,"")
N22: =IF(G22<>"",L22/M22,"")
N23: =IF(G23<>"",L23/M23,"")

Sheet reservas
A1: Meta | B1: Valor | C1: Prazo

Sheet icons
A1: Cartão | B1: Logo
A2: BTG | B2: https://play-lh.googleusercontent.com/O5Z9jsv79WTfdd37TFPyIwAQjNotIZTTEC6sOXaD3_2IXrMjtOI2ZnqReOicI3TgmqI
A3: AA - Santander | B3: https://assets.hgbrasil.com/finance/companies/big/santander-br.png
A4: Azul - Itau | B4: https://blogger.googleusercontent.com/img/b/R29vZ2xl/AVvXsEjl4gJnZqQz-Wz4S_mjixZgRnvCTYbIzoYs34k0e5qslitovNsUJbX8owsXEISCuHSFYbZ09JrRBr6sH3QaUm9TltnTRlyFnl9W2TW2T1iIMnB9MKpoMWMpZi0lY0uBU5cSYKi5i2Uy0XQucH0orBc8QCDtkRIkSB6SnaBhBmeB-SeGFVUiKF93/s510/itau%20logo%20novo%201.jpg
A5: Unq - Santander | B5: https://assets.hgbrasil.com/finance/companies/big/santander-br.png
A6: Elo | B6: https://www.publicitarioscriativos.com/wp-content/uploads/2024/05/442415684_844179061088736_7389654490654112245_n.jpg
A7: BB | B7: https://encrypted-tbn0.gstatic.com/images?q=tbn:ANd9GcSJysUOK4O3SeA8O0Zzn289tU16vROXFtKvEQ&s
A8: Itau | B8: https://blogger.googleusercontent.com/img/b/R29vZ2xl/AVvXsEjl4gJnZqQz-Wz4S_mjixZgRnvCTYbIzoYs34k0e5qslitovNsUJbX8owsXEISCuHSFYbZ09JrRBr6sH3QaUm9TltnTRlyFnl9W2TW2T1iIMnB9MKpoMWMpZi0lY0uBU5cSYKi5i2Uy0XQucH0orBc8QCDtkRIkSB6SnaBhBmeB-SeGFVUiKF93/s510/itau%20logo%20novo%201.jpg
A9: Caixa | B9: https://raichu-uploads.s3.amazonaws.com/logo_caixa-economica-federal_q9tWzt.png
A10: Santander | B10: https://assets.hgbrasil.com/finance/companies/big/santander-br.png
A11: Revolut | B11: https://www.logo.wine/a/logo/Revolut/Revolut-Logo.wine.svg
